Workbook

Sheet Overview
A1: OmniComm Wireless Intelligence Hub
A2: Custom-case build specification · Compute Module 5 platform · v1.0
A4: PROJECT SUMMARY
A5: Platform | B5: Raspberry Pi Compute Module 5 (CM5) — quad-core Cortex-A76 @ 2.4GHz, 4GB LPDDR4X, 32GB eMMC
A6: Carrier Board | B6: Waveshare CM5-DUAL-ETH-4G/5G-BASE — dual Ethernet, M.2 NVMe, M.2 4G/5G, 7-36V DC input
A7: Form Factor | B7: Custom metal case — single 230VAC inlet, dual RJ45, single external USB-A, antennas only
A8: Architecture Goal | B8: All wireless modules internal to case; external antennas via SMA bulkhead connectors
A9: Power Inputs | B9: 230VAC (primary) · PoE+ (backup) · 4×21700 Li-ion UPS (battery)
A10: Internet Paths | B10: Wired WAN (primary) · Wi-Fi client (failover) · 4G LTE cellular (tertiary)
A11: Wireless Coverage | B11: 8 dedicated radios — full sub-GHz, ISM, 2.4GHz, 5GHz, cellular coverage
A12: Software Base | B12: Raspberry Pi OS Bookworm + Home Assistant (Container) + OpenWRT (containerized router)
A13: Remote Access | B13: Nabu Casa Cloud (client) · Tailscale (admin) · Web Terminal (in-app)
A14: Target Use Case | B14: Single-box smart-home hub for high-end residential, architectural integrations
A17: COST SUMMARY
A18: Category | B18: Description | C18: Items | D18: Subtotal (EUR)
A19: Compute & Carrier | B19: CM5 module + Waveshare carrier board + NVMe SSD | C19: =COUNTIF(Hardware!E:E,"Core compute") -> 3 | D19: =SUMPRODUCT((Hardware!E5:E60="Core compute")*IFERROR(Hardware!G5:G60*Hardware!H5:H60,0)) -> 167
A20: Power & UPS | B20: AC-DC module + UPS HAT + 21700 cells + PoE module + IEC inlet | C20: =COUNTIF(Hardware!E:E,"Power") -> 5 | D20: =SUMPRODUCT((Hardware!E5:E60="Power")*IFERROR(Hardware!G5:G60*Hardware!H5:H60,0)) -> 128
A21: Cooling | B21: Active cooler + chassis exhaust fan | C21: =COUNTIF(Hardware!E:E,"Cooling") -> 2 | D21: =SUMPRODUCT((Hardware!E5:E60="Cooling")*IFERROR(Hardware!G5:G60*Hardware!H5:H60,0)) -> 30
A22: Internal USB hub | B22: 7-port industrial USB 2.0 hub PCB | C22: =COUNTIF(Hardware!E:E,"USB hub") -> 1 | D22: =SUMPRODUCT((Hardware!E5:E60="USB hub")*IFERROR(Hardware!G5:G60*Hardware!H5:H60,0)) -> 75
A23: Wireless radios | B23: Zigbee/Thread, Z-Wave, EnOcean, RTL-SDR, Wi-Fi 6 AP, Wi-Fi HaLow, NFC, 4G LTE | C23: =COUNTIF(Hardware!E:E,"Radio") -> 8 | D23: =SUMPRODUCT((Hardware!E5:E60="Radio")*IFERROR(Hardware!G5:G60*Hardware!H5:H60,0)) -> 445
A24: Case & antennas | B24: Custom case, SMA bulkheads + pigtails, external antennas | C24: =COUNTIF(Hardware!E:E,"Case") -> 6 | D24: =SUMPRODUCT((Hardware!E5:E60="Case")*IFERROR(Hardware!G5:G60*Hardware!H5:H60,0)) -> 177
A25: Optional / on request | B25: KNX TP USB interface + HackRF One | C25: =COUNTIF(Hardware!E:E,"Optional") -> 2 | D25: =SUMPRODUCT((Hardware!E5:E60="Optional")*IFERROR(Hardware!G5:G60*Hardware!H5:H60,0)) -> 350
A26: BASE BUILD TOTAL (excludes optional) | B26: Without Optional/on-request items | C26: =SUM(C19:C24) -> 25 | D26: =SUM(D19:D24) -> 1022
A27: GRAND TOTAL (all items) | B27: Including all optional items | C27: =SUM(C19:C25) -> 27 | D27: =SUM(D19:D25) -> 1372
A29: LEGEND
A30: Status: Core | B30: Part of standard build
A31: Status: Optional | B31: Available on client request or for specific use case
A32: Tier color: Built-in (green band) | B32: Native to CM5 or carrier board
A33: Tier color: USB Dongle (purple band) | B33: Internal USB-attached radio module
A34: Tier color: Network/Gateway (orange band) | B34: External via Ethernet or distributed node

Sheet Hardware
A1: Bill of Materials — Hardware
A2: Internal modules within the custom case · all radio dongles wired to internal USB hub
A4: CORE COMPUTE
A5: # | B5: Component | C5: Product / SKU | D5: Vendor | E5: Category | F5: Status | G5: Qty | H5: Unit € (net) | I5: Connection | J5: Notes / Why
A6: 1 | B6: CM5 module | C6: RPI-CM5-4GB-32GB | D6: RPi Foundation | E6: Core compute | F6: Core | G6: 1 | H6: 70 | I6: — | J6: Quad-core A76, 4GB RAM, 32GB eMMC, BT/WiFi
A7: 2 | B7: Carrier board | C7: Waveshare CM5-DUAL-ETH-4G/5G-BASE | D7: Waveshare | E7: Core compute | F7: Core | G7: 1 | H7: 52 | I7: — | J7: Dual Eth (GbE+2.5GbE), M.2 NVMe, M.2 4G/5G, 7-36V DC
A8: 3 | B8: NVMe SSD | C8: WD SN770 512GB M.2 2280 | D8: Western Digital | E8: Core compute | F8: Core | G8: 1 | H8: 45 | I8: M.2 M-Key | J8: Primary storage, PCIe Gen 2 ×1 on carrier
B9: Subtotal: CORE COMPUTE | H9: =SUMPRODUCT(G6:G8,H6:H8) -> 167
A11: POWER & UPS
A12: # | B12: Component | C12: Product / SKU | D12: Vendor | E12: Category | F12: Status | G12: Qty | H12: Unit € (net) | I12: Connection | J12: Notes / Why
A13: 4 | B13: AC-DC primary supply | C13: Mean Well RS-25-12 (25W, 12V) | D13: Mean Well | E13: Power | F13: Core | G13: 1 | H13: 15 | I13: Internal DC wire | J13: 230VAC → 12V to carrier DC input
A14: 5 | B14: IEC C14 inlet + fuse + switch | C14: Schaffner FN9244B or equiv. | D14: Schaffner | E14: Power | F14: Core | G14: 1 | H14: 8 | I14: 230VAC chassis | J14: Standard EU mains entry, EMI filter
A15: 6 | B15: UPS module | C15: Waveshare UPS HAT (E) | D15: Waveshare | E15: Power | F15: Core | G15: 1 | H15: 30 | I15: GPIO power only | J15: I2C battery monitor, 4× 21700 cells
A16: 7 | B16: UPS cells | C16: Samsung 21700 5000mAh ×4 | D16: Samsung INR | E16: Power | F16: Core | G16: 4 | H16: 10 | I16: — | J16: ~2 hrs runtime at idle hub load
A17: 8 | B17: PoE backup module | C17: Geekworm X15-POE1 (or equiv.) | D17: Geekworm | E17: Power | F17: Core | G17: 1 | H17: 35 | I17: GPIO + RJ45 | J17: Backup power path via Cat6 cable, IEEE 802.3at
B18: Subtotal: POWER & UPS | H18: =SUMPRODUCT(G13:G17,H13:H17) -> 128
A20: COOLING
A21: # | B21: Component | C21: Product / SKU | D21: Vendor | E21: Category | F21: Status | G21: Qty | H21: Unit € (net) | I21: Connection | J21: Notes / Why
A22: 9 | B22: CPU cooler | C22: Official RPi 5 Active Cooler | D22: RPi Foundation | E22: Cooling | F22: Core | G22: 1 | H22: 12 | I22: JST-SH 4-pin | J22: Mounts on CM5 via standard fan connector
A23: 10 | B23: Chassis exhaust fan | C23: Noctua NF-A8 5V | D23: Noctua | E23: Cooling | F23: Core | G23: 1 | H23: 18 | I23: USB 5V | J23: 80mm low-noise case ventilation
B24: Subtotal: COOLING | H24: =SUMPRODUCT(G22:G23,H22:H23) -> 30
A26: INTERNAL USB HUB
A27: # | B27: Component | C27: Product / SKU | D27: Vendor | E27: Category | F27: Status | G27: Qty | H27: Unit € (net) | I27: Connection | J27: Notes / Why
A28: 11 | B28: USB 2.0/3.0 hub PCB | C28: Coolgear CG-3510S7 7-port board | D28: Coolgear | E28: USB hub | F28: Core | G28: 1 | H28: 75 | I28: USB 3.0 internal | J28: MTT chip, ESD protected, OEM-style
B29: Subtotal: INTERNAL USB HUB | H29: =SUMPRODUCT(G28:G28,H28:H28) -> 75
A31: WIRELESS RADIOS
A32: # | B32: Component | C32: Product / SKU | D32: Vendor | E32: Category | F32: Status | G32: Qty | H32: Unit € (net) | I32: Connection | J32: Notes / Why
A33: 12 | B33: Zigbee + Thread | C33: Sonoff ZBDONGLE-E (EFR32MG21) | D33: Sonoff | E33: Radio | F33: Core | G33: 1 | H33: 30 | I33: USB hub port 1 | J33: Concurrent Zigbee 3.0 + Thread radio
A34: 13 | B34: Z-Wave 800 | C34: Aeotec Z-Stick 7 (ZWA010) | D34: Aeotec | E34: Radio | F34: Core | G34: 1 | H34: 45 | I34: USB hub port 2 | J34: Sub-GHz 868MHz, supports ZWLR-ready devices
A35: 14 | B35: EnOcean 868 | C35: EnOcean USB 300 (TCM310) | D35: EnOcean | E35: Radio | F35: Core | G35: 1 | H35: 30 | I35: USB hub port 3 | J35: Battery-free switches and sensors
A36: 15 | B36: RF receiver | C36: RTL-SDR Blog V4 | D36: RTL-SDR Blog | E36: Radio | F36: Core | G36: 1 | H36: 30 | I36: USB hub port 4 | J36: Passive RX 315/433/868/915 MHz
A37: 16 | B37: Wi-Fi 6 AP | C37: Comfast CF-953AX (MT7921AU) | D37: Comfast | E37: Radio | F37: Core | G37: 1 | H37: 35 | I37: USB hub port 5 | J37: Dedicated AP mode, 2.4+5GHz dual-band
A38: 17 | B38: NFC reader | C38: ACR122U (NXP PN532) | D38: ACS | E38: Radio | F38: Core | G38: 1 | H38: 40 | I38: USB hub port 6 | J38: NFC-A/B, ISO 14443, MIFARE, badge/keyfob
A39: 18 | B39: Wi-Fi HaLow | C39: Vantron VT-USB-AH-8108 (MM8108) | D39: Vantron | E39: Radio | F39: Core | G39: 1 | H39: 180 | I39: USB hub port 7 | J39: 802.11ah, sub-1GHz, 10× range vs Wi-Fi 6
A40: 19 | B40: 4G LTE + GNSS | C40: Waveshare SIM7600G-H-M.2 | D40: Waveshare | E40: Radio | F40: Core | G40: 1 | H40: 55 | I40: M.2 B-Key | J40: Backup internet, GPS positioning, on-carrier slot
B41: Subtotal: WIRELESS RADIOS | H41: =SUMPRODUCT(G33:G40,H33:H40) -> 445
A43: CASE & ANTENNAS
A44: # | B44: Component | C44: Product / SKU | D44: Vendor | E44: Category | F44: Status | G44: Qty | H44: Unit € (net) | I44: Connection | J44: Notes / Why
A45: 20 | B45: Custom metal case | C45: CNC aluminium or bent-metal | D45: Custom fab | E45: Case | F45: Core | G45: 1 | H45: 100 | I45: — | J45: ~220×160×60mm, single 230VAC + 2× RJ45 + 1× USB-A
A46: 21 | B46: SMA bulkhead set | C46: 8× SMA female-to-uFL pigtails | D46: Various | E46: Case | F46: Core | G46: 1 | H46: 20 | I46: Internal RF | J46: Antenna passthroughs for each dongle
...

Sheet Software
A1: Software Stack
A2: OS, services, add-ons, integrations — all components running on the hub
A4: BASE OPERATING SYSTEM
A5: # | B5: Software | C5: Role / Purpose | D5: License | E5: Layer | F5: Cost | G5: Notes
A6: 1 | B6: Raspberry Pi OS Bookworm 64-bit | C6: Host operating system, Debian-based | D6: Free / Open Source | E6: OS | F6: €0/yr | G6: Stable, well-supported, current LTS as of 2026
A7: 2 | B7: systemd-networkd + NetworkManager | C7: Network & VPN management | D7: Free / Open Source | E7: OS | F7: €0/yr | G7: Built into Raspberry Pi OS
A8: 3 | B8: Docker Engine + docker-compose | C8: Container runtime for all services | D8: Free / Open Source | E8: OS | F8: €0/yr | G8: All apps containerized, easy backup and migration
A10: ROUTER & NETWORK
A11: # | B11: Software | C11: Role / Purpose | D11: License | E11: Layer | F11: Cost | G11: Notes
A12: 4 | B12: OpenWrt (containerized) | C12: Multi-WAN failover, firewall, DHCP, NAT, VLAN | D12: Free / Open Source | E12: Network | F12: €0/yr | G12: Routes between WAN/LAN/4G with auto-failover
A13: 5 | B13: hostapd | C13: Wi-Fi access point daemon | D13: Free / Open Source | E13: Network | F13: €0/yr | G13: Drives Comfast CF-953AX as dedicated IoT AP
A14: 6 | B14: AdGuard Home | C14: Network-wide ad and tracker blocking | D14: Free / Open Source | E14: Network | F14: €0/yr | G14: DNS-based filtering, household-wide protection
A15: 7 | B15: Tailscale daemon | C15: Mesh VPN for remote admin access | D15: Freemium | E15: Network | F15: €0/yr | G15: Free tier covers up to 100 devices, WireGuard-based
A16: 8 | B16: ModemManager | C16: 4G LTE modem control + auto-reconnect | D16: Free / Open Source | E16: Network | F16: €0/yr | G16: Standard Linux modem control for SIM7600
A18: HOME ASSISTANT CORE
A19: # | B19: Software | C19: Role / Purpose | D19: License | E19: Layer | F19: Cost | G19: Notes
A20: 9 | B20: Home Assistant (HA Container) | C20: Smart home automation platform | D20: Free / Open Source | E20: Automation | F20: €0/yr | G20: Core dashboards, integrations, automations
A21: 10 | B21: HACS (Home Assistant Community Store) | C21: Custom integrations and dashboards repository | D21: Free / Open Source | E21: Automation | F21: €0/yr | G21: Third-party integrations beyond core HA
A22: 11 | B22: Mosquitto MQTT broker | C22: Message bus for Zigbee2MQTT and ESPHome | D22: Free / Open Source | E22: Automation | F22: €0/yr | G22: Internal pub/sub backbone
A23: 12 | B23: Nabu Casa Home Assistant Cloud | C23: Remote UI + voice + Google/Alexa bridges | D23: Subscription | E23: Cloud | F23: €75/yr | G23: Client-facing access, encryption, voice TTS/STT
A25: RADIO / PROTOCOL DRIVERS
A26: # | B26: Software | C26: Role / Purpose | D26: License | E26: Layer | F26: Cost | G26: Notes
A27: 13 | B27: Zigbee2MQTT | C27: Zigbee 3.0 device manager + Matter support | D27: Free / Open Source | E27: Protocol | F27: €0/yr | G27: Talks to ZBDONGLE-E, 3000+ device library
A28: 14 | B28: Z-Wave JS UI | C28: Z-Wave 800 controller + ZWLR ready | D28: Free / Open Source | E28: Protocol | F28: €0/yr | G28: Talks to Aeotec Z-Stick 7
A29: 15 | B29: ESPHome | C29: ESP32 fleet flashing + OTA management | D29: Free / Open Source | E29: Protocol | F29: €0/yr | G29: Provisions and maintains distributed nodes
A30: 16 | B30: OpenMQTTGateway | C30: Multi-protocol RF gateway firmware | D30: Free / Open Source | E30: Protocol | F30: €0/yr | G30: For external ESP32+NRF24L01 / CC1101 nodes
A31: 17 | B31: rtl_433 | C31: 433/868 MHz decoder for RTL-SDR | D31: Free / Open Source | E31: Protocol | F31: €0/yr | G31: Decodes weather stations, TPMS, doorbells, etc.
A32: 18 | B32: libnfc + nfcpy | C32: NFC reader stack for ACR122U | D32: Free / Open Source | E32: Protocol | F32: €0/yr | G32: MIFARE, ISO 14443 support
A33: 19 | B33: morse-firmware (HaLow) | C33: Wi-Fi HaLow MM8108 driver + tools | D33: Vendor-licensed | E33: Protocol | F33: €0/yr | G33: USB AP/STA control for HaLow IoT devices
A34: 20 | B34: knxd (if KNX TP present) | C34: KNX bus daemon | D34: Free / Open Source | E34: Protocol | F34: €0/yr | G34: Optional — only if Weinzierl 332 USB installed
A36: AUTOMATION & LOGIC
A37: # | B37: Software | C37: Role / Purpose | D37: License | E37: Layer | F37: Cost | G37: Notes
A38: 21 | B38: Node-RED | C38: Visual flow-based automation editor | D38: Free / Open Source | E38: Logic | F38: €0/yr | G38: Complex logic that survives HA updates
A39: 22 | B39: AppDaemon | C39: Python-based automation runtime (optional) | D39: Free / Open Source | E39: Logic | F39: €0/yr | G39: For advanced users / specific use cases
A41: DATA & DASHBOARDS
A42: # | B42: Software | C42: Role / Purpose | D42: License | E42: Layer | F42: Cost | G42: Notes
A43: 23 | B43: InfluxDB | C43: Time-series database for long-term sensor history | D43: Free / Open Source | E43: Data | F43: €0/yr | G43: Years of high-resolution sensor logging
A44: 24 | B44: Grafana | C44: Custom dashboards for energy + analytics | D44: Free / Open Source | E44: Data | F44: €0/yr | G44: Embedded in HA via iframe panel
A46: REMOTE ACCESS & ADMIN
A47: # | B47: Software | C47: Role / Purpose | D47: License | E47: Layer | F47: Cost | G47: Notes
...

Sheet Wireless
A1: Wireless Protocol Coverage
A2: All protocols covered (internally or via distributed nodes) · OmniComm spectrum
A4: CORE — BUILT INTO HUB
A5: # | B5: Protocol | C5: Path / Hardware | D5: Usage | E5: Frequency | F5: Bandwidth | G5: Status
A6: 1 | B6: Wi-Fi 4 / 5 / 6 (client) | C6: CM5 onboard BCM2712 + Comfast CF-953AX | D6: Connect hub to existing Wi-Fi networks | E6: 2.4 + 5 GHz | F6: Up to 866 Mbps | G6: Core
A7: 2 | B7: Wi-Fi 6 (AP mode) | C7: Comfast CF-953AX (MT7921AU) on internal USB hub | D7: Dedicated IoT VLAN AP with external antennas | E7: 2.4 + 5 GHz | F7: ~650 Mbps | G7: Core
A8: 3 | B8: Wi-Fi Direct | C8: Either Wi-Fi 6 chip in P2P mode | D8: Direct device-to-device pairing without router | E8: 2.4 + 5 GHz | F8: Up to 250 Mbps | G8: Core
A9: 4 | B9: Bluetooth Classic (BR/EDR) | C9: CM5 onboard BT 5.0 controller | D9: Headsets, legacy AV pairing | E9: 2.4 GHz | F9: 1–3 Mbps | G9: Core
A10: 5 | B10: Bluetooth LE 5.x | C10: CM5 onboard + distributed ESP32 BT proxies | D10: Sensors, beacons, BLE locks, body scales | E10: 2.4 GHz | F10: 1–2 Mbps | G10: Core
A11: 6 | B11: Bluetooth Mesh | C11: Same hardware, software stack | D11: Mesh lighting (Silvair, Casambi), industrial sensors | E11: 2.4 GHz | F11: 1 Mbps per node | G11: Core
A12: 7 | B12: Zigbee 3.0 | C12: Sonoff ZBDONGLE-E (EFR32MG21) on internal USB | D12: Bulbs, plugs, sensors, valves — 3000+ device ecosystem | E12: 2.4 GHz | F12: 250 kbps | G12: Core
A13: 8 | B13: Thread / Matter-over-Thread | C13: Shared ZBDONGLE-E concurrent radio | D13: Matter-certified devices, IPv6 mesh | E13: 2.4 GHz | F13: 250 kbps | G13: Core
A14: 9 | B14: 6LoWPAN | C14: Shared ZBDONGLE-E radio | D14: IPv6 over 802.15.4, foundation of Thread | E14: 2.4 GHz | F14: 250 kbps | G14: Core
A15: 10 | B15: Matter-over-Wi-Fi | C15: CM5 / Comfast Wi-Fi stack | D15: Matter devices using Wi-Fi transport | E15: 2.4 + 5 GHz | F15: Wi-Fi 6 limits | G15: Core
A16: 11 | B16: Z-Wave 800 / Plus / ZWLR | C16: Aeotec Z-Stick 7 (ZWA010) on internal USB | D16: Locks, alarm sensors, dimmers — sub-GHz reliability | E16: 868 MHz | F16: 9.6–100 kbps | G16: Core
A17: 12 | B17: EnOcean 868 MHz | C17: EnOcean USB 300 (TCM310) on internal USB | D17: Battery-free wireless switches and sensors | E17: 868 MHz | F17: 125 kbps | G17: Core
... A25: 20 | B25: NFC tags (NTAG215 etc.) | C25: HA Companion App on user's phone | D25: Scene triggers via phone tap to wall tag | E25: 13.56 MHz | F25: 106 kbps | G25: Core
A27: VIA DISTRIBUTED ESP32 NODES (External, room-level)
A28: # | B28: Protocol | C28: Path / Hardware | D28: Usage | E28: Frequency | F28: Bandwidth | G28: Status
A29: 21 | B29: Infrared (IR) | C29: Distributed ESP32 + IR LED per room (ESPHome) | D29: TVs, AV receivers, projectors, AC units | E29: IR optical | F29: Modulated 38kHz | G29: Core
A30: 22 | B30: 433/868 MHz bidirectional | C30: ESP32 + CC1101 transceiver (ESPHome) | D30: Roller shutters, RF switches, doorbells, RF outlets | E30: 433/868 MHz | F30: 1.2–500 kbps | G30: Core
A31: 23 | B31: Nordic ESB / Gazell | C31: ESP32 + NRF24L01+ via OpenMQTTGateway | D31: Niche legacy wireless peripherals | E31: 2.4 GHz | F31: 0.25–2 Mbps | G31: Optional
A32: 24 | B32: Proprietary Xiaomi/Tuya 2.4GHz | C32: Same ESP32 + NRF24L01+ approach | D32: Specific legacy non-Zigbee Mi devices | E32: 2.4 GHz | F32: Variable | G32: Optional
A33: 25 | B33: LF RFID 125 kHz (EM4100) | C33: ESP32 + RDM6300 at door (ESPHome) | D33: Legacy access systems already in place | E33: 125 kHz | F33: 4 kbps | G33: Optional
A34: 26 | B34: Bluetooth proxy extension | C34: ESP32 BT proxy nodes spread through building | D34: Extend BLE coverage beyond hub vicinity | E34: 2.4 GHz | F34: 1–2 Mbps | G34: Core
A36: VIA NETWORK / GATEWAY (External, IP-based)
A37: # | B37: Protocol | C37: Path / Hardware | D37: Usage | E37: Frequency | F37: Bandwidth | G37: Status
A38: 27 | B38: KNX IP | C38: CM5 Ethernet → existing KNX IP Router on LAN | D38: Professional building automation, DALI, façades | E38: Wired/IP | F38: 9.6 kbps logical | G38: Core
A39: 28 | B39: KNX TP (twisted pair) | C39: Weinzierl 332 USB on internal hub (optional) | D39: Direct KNX bus access without separate router | E39: Wired | F39: 9.6 kbps | G39: Optional
A40: 29 | B40: LoRa / LoRaWAN | C40: RAK7268 LoRaWAN gateway on Ethernet | D40: km-range garden, pool, outbuilding sensors | E40: 868 MHz | F40: 0.3–50 kbps | G40: Optional
A41: 30 | B41: Meshtastic | C41: LILYGO T-Beam over USB or Wi-Fi | D41: Off-grid encrypted mesh, perimeter, emergency | E41: 868 MHz | F41: 0.3–11 kbps | G41: Optional
A42: 31 | B42: Modbus RTU | C42: USB RS-485 adapter on internal hub (when needed) | D42: Solar inverters, heat pumps, HVAC, EV chargers | E42: Wired | F42: 9.6–115 kbps | G42: Optional
A44: NOT COVERED / NICHE — see notes
A45: # | B45: Protocol | C45: Path / Hardware | D45: Usage | E45: Frequency | F45: Bandwidth | G45: Status
A46: 32 | B46: Wi-Fi 7 (802.11be) | C46: ⚠ Skip — no stable USB AP-mode adapters yet | D46: Revisit 2027 when proper USB adapters mature | E46: — | F46: — | G46: Future
A47: 33 | B47: KNX RF | C47: ⚠ Niche — very rare in residential, capture via SDR | D47: Wireless KNX devices (uncommon) | E47: 868 MHz | F47: 16.4 kbps | G47: Future
A48: 34 | B48: NFC-F (FeliCa) | C48: ⚠ Japanese transit only, rarely relevant in EU | D48: Japanese transit and payment systems | E48: 13.56 MHz | F48: — | G48: Future
A49: 35 | B49: Full-band SDR TX 1MHz–6GHz | C49: ⚠ HackRF One on request only — research tool | D49: RF research, reverse engineering of proprietary | E49: 1MHz–6GHz | F49: 20 MHz BW | G49: Optional
B52: COVERAGE STATISTICS
B53: Total protocols covered (Core) | G53: =COUNTIF(G:G,"Core") -> 24
...

Sheet I-O Topology
A1: I/O Topology — Carrier Board Port Allocation
A2: Waveshare CM5-DUAL-ETH-4G/5G-BASE · all assignments
A4: PHYSICAL PORTS — CASE EXTERIOR
A5: # | B5: Port (carrier board) | C5: Type | D5: Assigned to | E5: Notes
A6: 1 | B6: RJ45 #1 (GbE) | C6: Ethernet 1 Gbps | D6: WAN / internet uplink | E6: Primary internet path, OpenWRT routes from here
A7: 2 | B7: RJ45 #2 (2.5 GbE) | C7: Ethernet 2.5 Gbps | D7: LAN / IoT VLAN + PoE camera switch | E7: Higher bandwidth for local high-speed devices
A8: 3 | B8: USB-A external | C8: USB 2.0 | D8: ESP32 provisioning port | E8: Only USB-A on case exterior, for occasional flashing
A9: 4 | B9: IEC C14 inlet | C9: 230VAC mains | D9: Primary AC power input | E9: Schuko/Type-F via supplied cable
A10: 5 | B10: SMA bulkheads × 9 | C10: RF coaxial | D10: External antennas | E10: Zigbee/Thread, Z-Wave, EnOcean, RTL-SDR, Wi-Fi 6 ×2, HaLow, LTE ×2, GPS
A12: INTERNAL — CARRIER BOARD
A13: # | B13: Port (carrier board) | C13: Type | D13: Assigned to | E13: Notes
A14: 6 | B14: USB 3.2 Gen1 #1 | C14: USB 3.0 | D14: Internal 7-port USB 2.0/3.0 hub | E14: Multiplied to 7 internal ports
A15: 7 | B15: USB 3.2 Gen1 #2 | C15: USB 3.0 | D15: Routed to case-exterior USB-A | E15: ESP32 provisioning port
A16: 8 | B16: USB 2.0 Type-C | C16: USB 2.0 | D16: Reserved — eMMC programming | E16: Accessible inside case for recovery flashing
A17: 9 | B17: M.2 M-Key | C17: PCIe Gen 2 ×1 | D17: NVMe SSD (WD SN770 512GB) | E17: Primary storage, 400+ MB/s sustained
A18: 10 | B18: M.2 B-Key | C18: PCIe + USB | D18: Waveshare SIM7600G-H-M.2 (4G LTE) | E18: Cellular backup + GPS, onboard Nano SIM slot
A19: 11 | B19: 40-pin GPIO header | C19: GPIO + I2C/SPI/UART | D19: Waveshare UPS HAT (E) — power only | E19: I2C battery monitoring, GPIO 2/3 reserved
A20: 12 | B20: 12V DC input (5.5×2.1) | C20: DC barrel | D20: Mean Well RS-25-12 output | E20: From internal AC-DC module
A21: 13 | B21: Fan header (JST-SH 4-pin) | C21: PWM fan | D21: Official RPi 5 Active Cooler | E21: CM5 PWM-controlled cooling
A22: 14 | B22: RTC battery socket | C22: CR/ML1220 | D22: Real-time clock backup cell | E22: Maintains time across power-off events
A23: 15 | B23: HDMI 0 | C23: HDMI 2.0 4K | D23: Capped — unused in hub | E23: Available for future external monitor
A24: 16 | B24: HDMI 1 | C24: HDMI 2.0 4K | D24: Capped — unused in hub | E24: Available for future external monitor
A25: 17 | B25: MIPI CAM/DISP 0 | C25: 4-lane MIPI | D25: Capped — unused in hub | E25: Hub does not host cameras or displays
A26: 18 | B26: MIPI CAM/DISP 1 | C26: 4-lane MIPI | D26: Capped — unused in hub | E26: Hub does not host cameras or displays
A28: INTERNAL USB HUB PORT ALLOCATION (7-port MTT)
A29: # | B29: Port (carrier board) | C29: Type | D29: Assigned to | E29: Notes
A30: 19 | B30: Hub port 1 | C30: USB 2.0 | D30: Sonoff ZBDONGLE-E | E30: Zigbee 3.0 + Thread
A31: 20 | B31: Hub port 2 | C31: USB 2.0 | D31: Aeotec Z-Stick 7 | E31: Z-Wave 800
A32: 21 | B32: Hub port 3 | C32: USB 2.0 | D32: EnOcean USB 300 | E32: 868 MHz battery-free switches
A33: 22 | B33: Hub port 4 | C33: USB 2.0 | D33: RTL-SDR Blog V4 | E33: RF receive 315/433/868/915 MHz
A34: 23 | B34: Hub port 5 | C34: USB 2.0 | D34: Comfast CF-953AX | E34: Wi-Fi 6 AP mode
A35: 24 | B35: Hub port 6 | C35: USB 2.0 | D35: ACR122U NFC reader | E35: NFC-A/B, ISO 14443, MIFARE
A36: 25 | B36: Hub port 7 | C36: USB 2.0 | D36: Vantron VT-USB-AH-8108 | E36: Wi-Fi HaLow sub-GHz IoT
